<?xml version='1.0'?>
<sdf version='1.4'>
  <model name="h-bot">
	<static>false</static> #Change this later
	  <link name='chassis'>
            <pose>0 0 .09 0 0 0</pose>

            <collision name='collision'>
              <geometry>
                <box>
                  <size>.6 .4 .1</size>
                </box>
              </geometry>
            </collision>

            <visual name='visual'>
              <geometry>
                <box>
                  <size>.6 .4 .1</size>
                </box>
              </geometry>
            </visual>
	</link>
	<link name="center_wheel">
	  <pose>0 0 .05 0 1.5707 1.5707</pose>
	   <collision name='center_wheel_collision'>
            <geometry>
              <cylinder>
                <radius>.05</radius>
		<length>.05</length>
              </cylinder>
            </geometry>

            <surface>
              <friction>
                <ode>
                  <mu>0</mu>
                  <mu2>0</mu2>
                  <slip1>1.0</slip1>
                  <slip2>1.0</slip2>
                </ode>
              </friction>
            </surface>
          </collision>

          <visual name='center_wheel_visual'>
            <pose>0 0 0 0 0 1.5707</pose>
            <geometry>
              <cylinder>
                <radius>.05</radius>
		<length>.05</length>
              </cylinder>
            </geometry>
          </visual>
          </link>
	<link name="left_front_wheel">
        <pose>-0.325 0.12 0.1 1.5707 1.5707 1.5707</pose>
        <collision name="collision">
          <geometry>
            <cylinder>
              <radius>.1</radius>
              <length>.05</length>
            </cylinder>
          </geometry>
        </collision>
        <visual name="visual">
          <geometry>
            <cylinder>
              <radius>.1</radius>
              <length>.05</length>
            </cylinder>
          </geometry>
        </visual>
      </link>
 	<link name="right_front_wheel">
        <pose>0.325 0.12 0.1 1.5707 1.5707 1.5707</pose>
        <collision name="collision">
          <geometry>
            <cylinder>
              <radius>.1</radius>
              <length>.05</length>
            </cylinder>
          </geometry>
        </collision>
        <visual name="visual">
          <geometry>
            <cylinder>
              <radius>.1</radius>
              <length>.05</length>
            </cylinder>
          </geometry>
        </visual>
      </link>
<link name="left_rear_wheel">
        <pose>-0.325 -0.12 0.1 1.5707 1.5707 1.5707</pose>
        <collision name="collision">
          <geometry>
            <cylinder>
              <radius>.1</radius>
              <length>.05</length>
            </cylinder>
          </geometry>
        </collision>
        <visual name="visual">
          <geometry>
            <cylinder>
              <radius>.1</radius>
              <length>.05</length>
            </cylinder>
          </geometry>
        </visual>
      </link>
 	<link name="right_rear_wheel">
        <pose>0.325 -0.12 0.1 1.5707 1.5707 1.5707</pose>
        <collision name="collision">
          <geometry>
            <cylinder>
              <radius>.1</radius>
              <length>.05</length>
            </cylinder>
          </geometry>
        </collision>
        <visual name="visual">
          <geometry>
            <cylinder>
              <radius>.1</radius>
              <length>.05</length>
            </cylinder>
          </geometry>
        </visual>
      </link>
      <joint type="revolute" name="left_front_wheel_hinge">
        <pose>-.03 0 0 0 0 0</pose>
        <child>left_front_wheel</child>
        <parent>chassis</parent>
        <axis>
          <xyz>1 0 0</xyz>
        </axis>
      </joint>

      <joint type="revolute" name="right_front_wheel_hinge">
        <pose>.03 0 0 0 0 0</pose>
        <child>right_front_wheel</child>
        <parent>chassis</parent>
        <axis>
          <xyz>1 0 0</xyz>
        </axis>
      </joint>
      <joint type="revolute" name="left_rear_wheel_hinge">
        <pose>-.03 0 0 0 0 0</pose>
        <child>left_rear_wheel</child>
        <parent>chassis</parent>
        <axis>
          <xyz>1 0 0</xyz>
        </axis>
      </joint>

      <joint type="revolute" name="right_rear_wheel_hinge">
        <pose>.03 0 0 0 0 0</pose>
        <child>right_rear_wheel</child>
        <parent>chassis</parent>
        <axis>
          <xyz>1 0 0</xyz>
        </axis>
      </joint>
      <joint type="revolute" name="center_wheel_hinge">
        <pose>.03 0 0 0 0 0</pose>
        <child>center_wheel</child>
        <parent>chassis</parent>
        <axis>
          <xyz>0 1 0</xyz>
        </axis>
      </joint>
  </model>
</sdf>
